Internal Server Error: /api/home_overview/
Traceback (most recent call last):
  File "/Users/Apple/Library/Python/3.9/lib/python/site-packages/django/core/handlers/exception.py", line 55, in inner
    response = get_response(request)
  File "/Users/Apple/Library/Python/3.9/lib/python/site-packages/django/core/handlers/base.py", line 197, in _get_response
    response = wrapped_callback(request, *callback_args, **callback_kwargs)
  File "/Users/Apple/Library/Python/3.9/lib/python/site-packages/django/views/decorators/csrf.py", line 56, in wrapper_view
    return view_func(*args, **kwargs)
  File "/Users/Apple/Library/Python/3.9/lib/python/site-packages/rest_framework/viewsets.py", line 124, in view
    return self.dispatch(request, *args, **kwargs)
  File "/Users/Apple/Library/Python/3.9/lib/python/site-packages/rest_framework/views.py", line 509, in dispatch
    response = self.handle_exception(exc)
  File "/Users/Apple/Library/Python/3.9/lib/python/site-packages/rest_framework/views.py", line 469, in handle_exception
    self.raise_uncaught_exception(exc)
  File "/Users/Apple/Library/Python/3.9/lib/python/site-packages/rest_framework/views.py", line 480, in raise_uncaught_exception
    raise exc
  File "/Users/Apple/Library/Python/3.9/lib/python/site-packages/rest_framework/views.py", line 506, in dispatch
    response = handler(request, *args, **kwargs)
  File "/Users/Apple/Open_source_project/himool_erp/HimoolERP/apps/statistic/views.py", line 385, in list
    is_void=False, team=self.team)
  File "/Users/Apple/Open_source_project/himool_erp/HimoolERP/extensions/viewsets.py", line 39, in team
    return self.request.user.team
AttributeError: 'AnonymousUser' object has no attribute 'team'
"GET /api/home_overview/ HTTP/1.1" 500 112936
